
<?xml version='1.0'?>
<sdf version="1.4">
  <model name="wheel">
    <pose>0 0.05 0.025 1.57079632679 0 0</pose>
<!--    <static>true</static>-->
      <link name="base">
        <!-- Offset the base by half the lenght of the cylinder -->
        <pose>0 0 0 0 0 0</pose>
        <inertial>
          <mass>1.2</mass>
          <inertia>
            <ixx>0.001087473</ixx>
            <iyy>0.001087473</iyy>
            <izz>0.001092437</izz>
            <ixy>0</ixy>
            <ixz>0</ixz>
            <iyz>0</iyz>
          </inertia>
        </inertial>
        <collision name="base_collision">
          <geometry>
            <cylinder>
              <!-- Radius and length provided by Velodyne -->
              <radius>.025</radius>
              <length>.02</length>
            </cylinder>
          </geometry>
        </collision>

        <!-- The visual is mostly a copy of the collision -->
        <visual name="base_visual">
          <geometry>
            <cylinder>
              <radius>.025</radius>
              <length>.02</length>
            </cylinder>
          </geometry>
        </visual>
    </link>

    <joint type="revolute" name="joint">

        <!-- Position the joint at the bottom of the top link -->
        <pose>0 0 0 0 0 0</pose>

        <!-- Use the base link as the parent of the joint -->
        <parent>base</parent>

        <!-- Use the top link as the child of the joint -->
        <child>top</child>

        <!-- The axis defines the joint's degree of freedom -->
        <axis>

          <!-- Revolve around the z-axis -->
          <xyz>0 0 1</xyz>

          <!-- Limit refers to the range of motion of the joint -->
          <limit>

            <!-- Use a very large number to indicate a continuous revolution -->
            <lower>-10000000000000000</lower>
            <upper>10000000000000000</upper>
          </limit>
        </axis>
      </joint>
  </model>
</sdf>